<?xml version="1.0"?>
<robot name="nino">

  <!-- Used for fixing robot to Gazebo 'base_link' -->
  <link name="world"/>

  <joint name="fixed" type="fixed">
    <parent link="world"/>
    <child link="base_link"/>
   <origin rpy="0 0 0" xyz="0 0 0.3"/>
  </joint>


  <link name="base_link">	
	<visual>
	   <origin xyz="0 0 0.029" rpy="1.57 0 -1.57"/>
	   <geometry>
		<mesh filename="package://nino_description/meshes/collada/torso.dae" scale="0.001 0.001 0.001"/>
 	   </geometry>
	   <material name="Red"/>
	</visual>
<collision>
   	  <geometry>
    		<cylinder length="0.03" radius="0.01"/>
          </geometry>
</collision>

 <inertial>
        <origin xyz="0 -0.012212 0.028064"/>
    	<mass value="0.34"/>
    	<inertia ixx="0.1" ixy="0" ixz="0" iyy="0.1" iyz="0" izz="0.1"/>
 </inertial>

  </link>

  <link name="left_shoulder_roll_link">
	<visual>
	   <origin xyz="0 0 -0.0274" rpy="-1.57 0 0"/>
	   <geometry>
		<mesh filename="package://nino_description/meshes/collada/ST-11-RV1.dae" scale="0.001 0.001 0.001"/>
 	   </geometry>
	   <material name="DarkGrey"/>
	</visual>
<collision>
<origin xyz="0 0 -0.08"/>
   	  <geometry>
    		<cylinder length="0.03" radius="0.01"/>
          </geometry>
</collision>

 <inertial>
	<origin xyz="0 -0.011 0"/>
    	<mass value="0.011"/>
    	<inertia ixx="0.1" ixy="0" ixz="0" iyy="0.1" iyz="0" izz="0.1"/>
 </inertial>
  </link>

 
  <link name="right_shoulder_roll_link">
	<visual>
	   <origin xyz="0 0 0.0274" rpy="1.57 0 3.14"/>
	   <geometry>
		<mesh filename="package://nino_description/meshes/collada/ST-11-RV1.dae" scale="0.001 0.001 0.001"/>
 	   </geometry>
	   <material name="DarkGrey"/>
	</visual>
<collision>
<origin xyz="0 0 0.08"/>
   	  <geometry>
    		<cylinder length="0.03" radius="0.01"/>
          </geometry>
</collision>

 <inertial>
	<origin xyz="0 -0.011 0"/>
    	<mass value="0.011"/>
    	<inertia ixx="0.1" ixy="0" ixz="0" iyy="0.1" iyz="0" izz="0.1"/>
 </inertial>
</link>


  <link name="left_shoulder_pitch_link">

<visual>
	   <origin xyz="0.01568 -0.012654 0.004478" rpy="0 1.57 -1.57"/>
	   <geometry>
	<mesh filename="package://nino_description/meshes/collada/shoulder_pitch_link.dae" scale="0.001 0.001 0.001"/>
 	   </geometry>
	   <material name="DarkGrey"/>
</visual>

<collision>
   	  <geometry>
    		<cylinder length="0.06" radius="0.02"/>
          </geometry>
</collision>

 <inertial>
	<origin xyz="-0.003204 0.007017 -0.012562"/>
    	<mass value="0.073"/>
    	<inertia ixx="0.16" ixy="0" ixz="0.000000016" iyy="0.1" iyz="0.000000076" izz="0.1"/>
 </inertial>

</link>

  <link name="right_shoulder_pitch_link">

<visual>
	   <origin xyz="0.01568 0.012654 -0.004478" rpy="0 -1.57 -1.57"/>
	   <geometry>
	<mesh filename="package://nino_description/meshes/collada/shoulder_pitch_link.dae" scale="0.001 0.001 0.001"/>
 	   </geometry>
	   <material name="DarkGrey"/>
</visual>
<collision>
   	  <geometry>
    		<cylinder length="0.06" radius="0.02"/>
          </geometry>
</collision>

 <inertial>
        <origin xyz="-0.003204 0.007017 -0.012562"/>
    	<mass value="0.073"/>
    	<inertia ixx="0.1" ixy="-0.000001662" ixz="0.000000016" iyy="0.1" iyz="0.000000076" izz="0.1"/>
 </inertial>

</link>


  <link name="left_elbow_pitch_link">
<visual>
	   <origin xyz="0.01568 0 0.004138" rpy="0 -1.57 1.57"/>
	   <geometry>
		<mesh filename="package://nino_description/meshes/collada/ax-12.dae" scale="0.001 0.001 0.001"/>
 	   </geometry>
	   <material name="DarkGrey"/>
</visual>

<collision>
   	  <geometry>
    		<cylinder length="0.06" radius="0.02"/>
          </geometry>
</collision>

 <inertial>
        <origin xyz="-0.002774 0.002536 0.000117"/>
    	<mass value="0.058"/>
    	<inertia ixx="0.1" ixy="-0.00000529156" ixz="-0.00000012797" iyy="0.1" iyz="-0.000000011641" izz="0.1"/>
 </inertial>
</link>


  <link name="right_elbow_pitch_link">
<visual>
	   <origin xyz="0.01568 0 -0.004478" rpy="0 1.57 1.57"/>
	   <geometry>
		<mesh filename="package://nino_description/meshes/collada/ax-12.dae" scale="0.001 0.001 0.001"/>
 	   </geometry>
	   <material name="DarkGrey"/>
	</visual>
<collision>
   	  <geometry>
    		<cylinder length="0.06" radius="0.02"/>
          </geometry>
</collision>

 <inertial>
        <origin xyz="-0.002774 0.002536 0.000117"/>
    	<mass value="0.058"/>
    	<inertia ixx="0.1" ixy="-0.00000529156" ixz="-0.00000012797" iyy="0.1" iyz="-0.000000011641" izz="0.1"/>
 </inertial>

</link>

 <link name="left_hand_endeffector_link"/>
  <link name="right_hand_endeffector_link"/>

<link name="left_hand_endeffector_frame_link"/>
<link name="right_hand_endeffector_frame_link"/>

  <link name="left_hip_roll_link">

        <visual>
	   <origin xyz="0.066833 0.01449 -0.00886" rpy=" -1.57 0 3.14"/>
	   <geometry>
	   <mesh filename="package://nino_description/meshes/collada/left_hip_roll_link.dae" scale="0.001 0.001 0.001"/>
 	   </geometry>
	   <material name="DarkGrey"/>
	</visual>

<collision>
   	  <geometry>
    		<cylinder length="0.06" radius="0.009"/>
          </geometry>
</collision>

 <inertial>
        <origin xyz="0.008824 -0.002922 -0.000704"/>
    	<mass value="0.088"/>
    	<inertia ixx="0.1" ixy="0.000003203" ixz="-0.000004246" iyy="0.1" iyz="0.000000843" izz="0.1"/>
 </inertial>

</link>


  <link name="right_hip_roll_link">

              <visual>
	   <origin xyz="0.061161 -0.015704 -0.00886" rpy=" -1.57 0 0"/>
	   <geometry>
	   <mesh filename="package://nino_description/meshes/collada/right_hip_roll_link.dae" scale="0.001 0.001 0.001"/>
 	   </geometry>
	   <material name="DarkGrey"/>
	</visual>

<collision>
   	  <geometry>
    		<cylinder length="0.06" radius="0.009"/>
          </geometry>
</collision>

 <inertial>
        <origin xyz="-0.003153 -0.002922 0.000926"/>
    	<mass value="0.088"/>
    	<inertia ixx="0.1" ixy="-0.000003203" ixz="0.000004246" iyy="0.1" iyz="0.000000843" izz="0.1"/>
 </inertial>
</link>


  <link name="left_hip_pitch_link">
        <visual>
	   <origin xyz="0.041011 -0.018297 0" rpy=" 0 3.14 0"/>
	   <geometry>
	   <mesh filename="package://nino_description/meshes/collada/ST-13-RV4.dae" scale="0.001 0.001 0.001"/>
 	   </geometry>
	   <material name="DarkGrey"/>
	</visual>
<collision>
   	  <geometry>
    		<cylinder length="0.06" radius="0.02"/>
          </geometry>
</collision>

 <inertial>
        <origin xyz="0.003389 0.016729 0"/>
    	<mass value="0.018"/>
    	<inertia ixx="0.1" ixy="0.000001306" ixz="0" iyy="0.1" iyz="0" izz="0.1"/>
 </inertial>
</link>


  <link name="right_hip_pitch_link">
  <visual>
	   <origin xyz="0.041011 -0.018297 0" rpy=" 0 3.14 0"/>
	   <geometry>
	   <mesh filename="package://nino_description/meshes/collada/ST-13-RV4.dae" scale="0.001 0.001 0.001"/>
 	   </geometry>
	   <material name="DarkGrey"/>
	</visual>

<collision>
   	  <geometry>
    		<cylinder length="0.06" radius="0.02"/>
          </geometry>
</collision>

 <inertial>
        <origin xyz="0.003389 0.016729 0"/>
    	<mass value="0.018"/>
    	<inertia ixx="0.1" ixy="0.000001306" ixz="0" iyy="0.1" iyz="0" izz="0.1"/>
 </inertial>

</link>


  <link name="left_knee_pitch_link">

<visual>
	   <origin xyz="-0.002836 -0.01297 -0.024736" rpy=" 3.14 0 0"/>
	   <geometry>
	   <mesh filename="package://nino_description/meshes/collada/knee_link.dae" scale="0.001 0.001 0.001"/>
 	   </geometry>
	   <material name="DarkGrey"/>
	</visual>
<collision>
   	  <geometry>
    		<cylinder length="0.06" radius="0.02"/>
          </geometry>
</collision>

 <inertial>
        <origin xyz="0.025432 -0.005388 -0.026434"/>
    	<mass value="0.0149"/>
    	<inertia ixx="0.1" ixy="0.000012048" ixz="0.000000311" iyy="0.1" iyz="0.000000311" izz="0.1"/>
 </inertial>


</link>

  <link name="right_knee_pitch_link">

<visual>
	   <origin xyz="-0.002836 -0.01297 -0.024736" rpy=" 3.14 0 0"/>
	   <geometry>
	   <mesh filename="package://nino_description/meshes/collada/knee_link.dae" scale="0.001 0.001 0.001"/>
 	   </geometry>
	   <material name="DarkGrey"/>
	</visual>
<collision>
   	  <geometry>
    		<cylinder length="0.06" radius="0.02"/>
          </geometry>
</collision>

 <inertial>
        <origin xyz="0.025432 -0.005388 -0.026434"/>
    	<mass value="0.0149"/>
    	<inertia ixx="0.1" ixy="0.000012048" ixz="0.000000311" iyy="0.1" iyz="0.000000311" izz="0.1"/>
 </inertial>

</link>


  <link name="left_foot_pitch_link">

<visual>
	   <origin xyz="0.039468 -0.002175 0.00247" rpy=" 1.57 0 0"/>
	   <geometry>
	   <mesh filename="package://nino_description/meshes/collada/left_foot_pitch_link.dae" scale="0.001 0.001 0.001"/>
 	   </geometry>
	   <material name="DarkGrey"/>
	</visual>
<collision>
   	  <geometry>
    		<cylinder length="0.06" radius="0.02"/>
          </geometry>
</collision>

 <inertial>
        <origin xyz="-0.001266 -0.001930 -0.001767"/>
    	<mass value="0.086"/>
    	<inertia ixx="0.1" ixy="-0.0000000362" ixz="-0.0000000144" iyy="0.1" iyz="0.0000000303" izz="0.1"/>
 </inertial>

</link>


  <link name="right_foot_pitch_link">
<visual>
	   <origin xyz="0.045139 -0.002175 -0.00247" rpy=" -1.57 0 3.14"/>
	   <geometry>
	   <mesh filename="package://nino_description/meshes/collada/right_foot_pitch_link.dae" scale="0.001 0.001 0.001"/>
 	   </geometry>
	   <material name="DarkGrey"/>
	</visual>

<collision>
   	  <geometry>
    		<cylinder length="0.06" radius="0.02"/>
          </geometry>
</collision>

 <inertial>
        <origin xyz="0.006937 -0.001930 -0.001767"/>
    	<mass value="0.086"/>
    	<inertia ixx="0.1" ixy="0.0000000362" ixz="0.0000000144" iyy="0.1" iyz="0.0000000303" izz="0.1"/>
 </inertial>
</link>

  <link name="left_foot_roll_link">
<visual>
	   <origin xyz="0.0357 0.01963 0" rpy="0 -1.57 -1.57"/>
	   <geometry>
	   <mesh filename="package://nino_description/meshes/collada/left_foot_roll_link.dae" scale="0.001 0.001 0.001"/>
 	   </geometry>
	   <material name="DarkGrey"/>
	</visual>

<collision>
   	  <geometry>
    		<cylinder length="0.06" radius="0.02"/>
          </geometry>
</collision>

 <inertial>
        <origin xyz="-0.000904 -0.007296 -0.003738"/>
    	<mass value="0.025"/>
    	<inertia ixx="0.1" ixy="0.000000180" ixz="0.000000084" iyy="0.1" iyz="-0.000001971" izz="0.1"/>
 </inertial>


</link>

  <link name="right_foot_roll_link">

<visual>
	   <origin xyz="0.0357 -0.018923 0" rpy="0 1.57 -1.57"/>
	   <geometry>
	   <mesh filename="package://nino_description/meshes/collada/right_foot_roll_link.dae" scale="0.001 0.001 0.001"/>

 	   </geometry>
	   <material name="DarkGrey"/>
	</visual>
<collision>
   	  <geometry>
    		<cylinder length="0.06" radius="0.02"/>
          </geometry>
</collision>

 <inertial>
        <origin xyz="0.000904 -0.007296 -0.003031"/>
    	<mass value="0.025"/>
    	<inertia ixx="0.1" ixy="-0.000000180" ixz="-0.000000084" iyy="0.1" iyz="-0.000001971" izz="0.1"/>
 </inertial>


</link>

  <link name="left_foot_endeffector_link"/>

 <link name="right_foot_endeffector_link"/>  

  <link name="left_foot_endeffector_frame_link"/>
  <link name="right_foot_endeffector_frame_link"/>


  <joint name="left_shoulder_roll_joint" type="revolute">
    <parent link="base_link"/>
    <child link="left_shoulder_roll_link"/>
    <origin rpy="0 1.57 1.57" xyz="0 0.088 0.0488"/>
    <axis xyz="0 0 1" />
    <limit effort="30" velocity="0.1" lower="-1.57" upper="1.57"/>
    <dynamics damping="5" friction="1"/>
  </joint>


  <joint name="right_shoulder_roll_joint" type="revolute">
    <parent link="base_link"/>
    <child link="right_shoulder_roll_link"/>
    <origin rpy="0 1.57 1.57" xyz="0 -0.088 0.0488"/>
    <axis xyz="0 0 1" />
    <limit effort="300" velocity="0.1" lower="-1.57" upper="1.57"/>
    <dynamics damping="50" friction="1"/>
  </joint>


<joint name="left_shoulder_pitch_joint" type="revolute">
    <parent link="left_shoulder_roll_link"/>
    <child link="left_shoulder_pitch_link"/>
    <origin rpy="0 -1.57 0" xyz="0 0 0"/>
    <axis xyz="0 0 1" />
    <limit effort="300" velocity="0.1" lower="-1.57" upper="1.57"/>
    <dynamics damping="50" friction="1"/>
  </joint>


  <joint name="right_shoulder_pitch_joint" type="revolute">
    <parent link="right_shoulder_roll_link"/>
    <child link="right_shoulder_pitch_link"/>
    <origin rpy="0 1.57 0" xyz="0 0 0"/>
    <axis xyz="0 0 1" />
    <limit effort="300" velocity="0.1" lower="-1.57" upper="1.57"/>
    <dynamics damping="50" friction="1"/>
  </joint>

<joint name="left_elbow_pitch_joint" type="revolute">
    <parent link="left_shoulder_pitch_link"/>
    <child link="left_elbow_pitch_link"/>
    <origin rpy="0 0 0" xyz="0.081 0 0"/>
    <axis xyz="0 0 1" />
    <limit effort="300" velocity="0.1" lower="-1.57" upper="1.57"/>
    <dynamics damping="50" friction="1"/>
  </joint>


  <joint name="right_elbow_pitch_joint" type="revolute">
    <parent link="right_shoulder_pitch_link"/>
    <child link="right_elbow_pitch_link"/>
    <origin rpy="0 0 0" xyz="0.081 0 0"/>
    <axis xyz="0 0 1" />
    <limit effort="300" velocity="0.1" lower="-1.57" upper="1.57"/>
    <dynamics damping="50" friction="1"/>
  </joint>

<joint name="left_hand_endeffector_joint" type="fixed">
    <parent link="left_elbow_pitch_link"/>
    <child link="left_hand_endeffector_link"/>
    <origin rpy="0 0 0" xyz="0.097 0 0"/>
     </joint>


<joint name="right_hand_endeffector_joint" type="fixed">
    <parent link="right_elbow_pitch_link"/>
    <child link="right_hand_endeffector_link"/>
    <origin rpy="0 0 0" xyz="0.097 0 0"/>
     </joint>

<joint name="left_hand_endeffector_frame" type="fixed">
    <parent link="left_hand_endeffector_link"/>
    <child link="left_hand_endeffector_frame_link"/>
    <origin rpy="0 0 -1.57" xyz="0 0 0"/>
     </joint>


<joint name="right_hand_endeffector_frame" type="fixed">
    <parent link="right_hand_endeffector_link"/>
    <child link="right_hand_endeffector_frame_link"/>
    <origin rpy="3.14 0 -1.57" xyz="0 0 0"/>
     </joint>


<!-- Upper Body Ends Here-->

  <joint name="left_hip_roll_joint" type="revolute">
    <parent link="base_link"/>
    <child link="left_hip_roll_link"/>
    <origin rpy="0 2.5 0" xyz="0 0.017 -0.025"/>
    <axis xyz="0 0 1" />
    <limit effort="300" velocity="0.1" lower="-1.57" upper="1.57"/>
    <dynamics damping="50" friction="1"/>
  </joint>

 
  <joint name="right_hip_roll_joint" type="revolute">
    <parent link="base_link"/>
    <child link="right_hip_roll_link"/>
    <origin rpy="0 1.57 0" xyz="0 -0.017 -0.025"/>
    <axis xyz="0 0 1" />
    <limit effort="300" velocity="0.1" lower="-1.57" upper="1.57"/>
    <dynamics damping="50" friction="1"/>
  </joint>


<joint name="left_hip_pitch_joint" type="revolute">
    <parent link="left_hip_roll_link"/>
    <child link="left_hip_pitch_link"/>
    <origin rpy="-1.57 0 0" xyz="0.0644 0.0161 0.004"/>
    <axis xyz="0 0 1" />
    <limit effort="300" velocity="0.1" lower="-1.57" upper="1.57"/>
    <dynamics damping="50" friction="1"/>
  </joint>


  <joint name="right_hip_pitch_joint" type="revolute">
    <parent link="right_hip_roll_link"/>
    <child link="right_hip_pitch_link"/>
    <origin rpy="-1.57 0 0" xyz="0.0644 -0.0161 0.004"/>
    <axis xyz="0 0 1" />
    <limit effort="300" velocity="0.1" lower="-1.57" upper="1.57"/>
    <dynamics damping="50" friction="1"/>
  </joint>

 <joint name="left_knee_pitch_joint" type="revolute">
    <parent link="left_hip_pitch_link"/>
    <child link="left_knee_pitch_link"/>
    <origin rpy="0 0 0" xyz="0.075011 0.011703 0"/>
    <axis xyz="0 0 1" />
    <limit effort="300" velocity="0.1" lower="-1.57" upper="1.57"/>
    <dynamics damping="50" friction="1"/>
  </joint>

 
  <joint name="right_knee_pitch_joint" type="revolute">
    <parent link="right_hip_pitch_link"/>
    <child link="right_knee_pitch_link"/>
    <origin rpy="0 0 0" xyz="0.075011 0.011703 0"/>
    <axis xyz="0 0 1" />
    <limit effort="300" velocity="0.1" lower="-1.57" upper="1.57"/>
    <dynamics damping="50" friction="1"/>
  </joint>

<joint name="left_foot_pitch_joint" type="revolute">
    <parent link="left_knee_pitch_link"/>
    <child link="left_foot_pitch_link"/>
    <origin xyz="0.05660 -0.004 0"/>
    <axis xyz="0 0 1" />
    <limit effort="300" velocity="0.1" lower="-1.57" upper="1.57"/>
    <dynamics damping="50" friction="1"/>
  </joint>

 
  <joint name="right_foot_pitch_joint" type="revolute">
    <parent link="right_knee_pitch_link"/>
    <child link="right_foot_pitch_link"/>
    <origin xyz="0.056 -0.004 0"/>
    <axis xyz="0 0 1" />
    <limit effort="300" velocity="0.1" lower="-1.57" upper="1.57"/>
    <dynamics damping="50" friction="1"/>
  </joint>

 <joint name="left_foot_roll_joint" type="revolute">
    <parent link="left_foot_pitch_link"/>
    <child link="left_foot_roll_link"/>
    <origin rpy="1.57 0 0" xyz="0.042 0 -0.0105"/>
    <axis xyz="0 0 1" />
    <limit effort="300" velocity="0.1" lower="-1.57" upper="1.57"/>
    <dynamics damping="50" friction="1"/>
  </joint>

 
  <joint name="right_foot_roll_joint" type="revolute">
    <parent link="right_foot_pitch_link"/>
    <child link="right_foot_roll_link"/>
    <origin rpy="1.57 0 0" xyz="0.042 0 0.0105"/>
    <axis xyz="0 0 1" />
    <limit effort="300" velocity="0.1" lower="-1.57" upper="1.57"/>
    <dynamics damping="50" friction="1"/>
  </joint>

  <joint name="left_foot_endeffector" type="fixed">
    <parent link="left_foot_roll_link"/>
    <child link="left_foot_endeffector_link"/>
    <origin rpy="0 0 0" xyz="0.036 0.010 0"/>
    </joint>

 
  <joint name="right_foot_endeffector" type="fixed">
    <parent link="right_foot_roll_link"/>
    <child link="right_foot_endeffector_link"/>
    <origin rpy="0 0 0" xyz="0.036 -0.010 0"/>
    </joint>

 <joint name="left_foot_endeffector_frame" type="fixed">
    <parent link="left_foot_endeffector_link"/>
    <child link="left_foot_endeffector_frame_link"/>
    <origin rpy="0 -1.57 0" xyz="0 0 0"/>
    </joint>

 
  <joint name="right_foot_endeffector_frame" type="fixed">
    <parent link="right_foot_endeffector_link"/>
    <child link="right_foot_endeffector_frame_link"/>
    <origin rpy="0 -1.57 0" xyz="0 0 0"/>
    </joint>

<transmission name="left_shoulder_roll_joint_tran">
    <type>transmission_interface/SimpleTransmission</type>
    <joint name="left_shoulder_roll_joint">
      <hardwareInterface>EffortJointInterface</hardwareInterface>
    </joint>
    <actuator name="left_shoulder_roll_joint_motor">
      <hardwareInterface>EffortJointInterface</hardwareInterface>
      <mechanicalReduction>1</mechanicalReduction>
    </actuator>
</transmission>

<transmission name="right_shoulder_roll_joint_tran">
    <type>transmission_interface/SimpleTransmission</type>
    <joint name="right_shoulder_roll_joint">
      <hardwareInterface>EffortJointInterface</hardwareInterface>
    </joint>
    <actuator name="right_shoulder_roll_joint_motor">
      <hardwareInterface>EffortJointInterface</hardwareInterface>
      <mechanicalReduction>1</mechanicalReduction>
    </actuator>
</transmission>


<transmission name="left_shoulder_pitch_joint_tran">
    <type>transmission_interface/SimpleTransmission</type>
    <joint name="left_shoulder_pitch_joint">
      <hardwareInterface>EffortJointInterface</hardwareInterface>
    </joint>
    <actuator name="left_shoulder_pitch_joint_motor">
      <hardwareInterface>EffortJointInterface</hardwareInterface>
      <mechanicalReduction>1</mechanicalReduction>
    </actuator>
</transmission>

<transmission name="right_shoulder_pitch_joint_tran">
    <type>transmission_interface/SimpleTransmission</type>
    <joint name="right_shoulder_pitch_joint">
      <hardwareInterface>EffortJointInterface</hardwareInterface>
    </joint>
    <actuator name="right_shoulder_pitch_joint_motor">
      <hardwareInterface>EffortJointInterface</hardwareInterface>
      <mechanicalReduction>1</mechanicalReduction>
    </actuator>
</transmission>

<transmission name="left_elbow_pitch_joint_tran">
    <type>transmission_interface/SimpleTransmission</type>
    <joint name="left_elbow_pitch_joint">
      <hardwareInterface>EffortJointInterface</hardwareInterface>
    </joint>
    <actuator name="left_elbow_pitch_joint_motor">
      <hardwareInterface>EffortJointInterface</hardwareInterface>
      <mechanicalReduction>1</mechanicalReduction>
    </actuator>
</transmission>

<transmission name="right_elbow_pitch_joint_tran">
    <type>transmission_interface/SimpleTransmission</type>
    <joint name="right_elbow_pitch_joint">
      <hardwareInterface>EffortJointInterface</hardwareInterface>
    </joint>
    <actuator name="right_elbow_pitch_joint_motor">
      <hardwareInterface>EffortJointInterface</hardwareInterface>
      <mechanicalReduction>1</mechanicalReduction>
    </actuator>
</transmission>

<transmission name="left_hip_roll_joint_tran">
    <type>transmission_interface/SimpleTransmission</type>
    <joint name="left_hip_roll_joint">
      <hardwareInterface>EffortJointInterface</hardwareInterface>
    </joint>
    <actuator name="left_hip_roll_joint_motor">
      <hardwareInterface>EffortJointInterface</hardwareInterface>
      <mechanicalReduction>1</mechanicalReduction>
    </actuator>
</transmission>

<transmission name="right_hip_roll_joint_tran">
    <type>transmission_interface/SimpleTransmission</type>
    <joint name="right_hip_roll_joint">
      <hardwareInterface>EffortJointInterface</hardwareInterface>
    </joint>
    <actuator name="right_hip_roll_joint_motor">
      <hardwareInterface>EffortJointInterface</hardwareInterface>
      <mechanicalReduction>1</mechanicalReduction>
    </actuator>
</transmission>


<transmission name="left_hip_pitch_joint_tran">
    <type>transmission_interface/SimpleTransmission</type>
    <joint name="left_hip_pitch_joint">
      <hardwareInterface>EffortJointInterface</hardwareInterface>
    </joint>
    <actuator name="left_hip_pitch_joint_motor">
      <hardwareInterface>EffortJointInterface</hardwareInterface>
      <mechanicalReduction>1</mechanicalReduction>
    </actuator>
</transmission>

<transmission name="right_hip_pitch_joint_tran">
    <type>transmission_interface/SimpleTransmission</type>
    <joint name="right_hip_pitch_joint">
      <hardwareInterface>EffortJointInterface</hardwareInterface>
    </joint>
    <actuator name="right_hip_pitch_joint_motor">
      <hardwareInterface>EffortJointInterface</hardwareInterface>
      <mechanicalReduction>1</mechanicalReduction>
    </actuator>
</transmission>

<transmission name="left_knee_pitch_joint_tran">
    <type>transmission_interface/SimpleTransmission</type>
    <joint name="left_knee_pitch_joint">
      <hardwareInterface>EffortJointInterface</hardwareInterface>
    </joint>
    <actuator name="left_knee_pitch_joint_motor">
      <hardwareInterface>EffortJointInterface</hardwareInterface>
      <mechanicalReduction>1</mechanicalReduction>
    </actuator>
</transmission>

<transmission name="right_knee_pitch_joint_tran">
    <type>transmission_interface/SimpleTransmission</type>
    <joint name="right_knee_pitch_joint">
      <hardwareInterface>EffortJointInterface</hardwareInterface>
    </joint>
    <actuator name="right_knee_pitch_joint_motor">
      <hardwareInterface>EffortJointInterface</hardwareInterface>
      <mechanicalReduction>1</mechanicalReduction>
    </actuator>
</transmission>

<transmission name="left_foot_pitch_joint_tran">
    <type>transmission_interface/SimpleTransmission</type>
    <joint name="left_foot_pitch_joint">
      <hardwareInterface>EffortJointInterface</hardwareInterface>
    </joint>
    <actuator name="left_foot_pitch_joint_motor">
      <hardwareInterface>EffortJointInterface</hardwareInterface>
      <mechanicalReduction>1</mechanicalReduction>
    </actuator>
</transmission>

<transmission name="right_foot_pitch_joint_tran">
    <type>transmission_interface/SimpleTransmission</type>
    <joint name="right_foot_pitch_joint">
      <hardwareInterface>EffortJointInterface</hardwareInterface>
    </joint>
    <actuator name="right_foot_pitch_joint_motor">
      <hardwareInterface>EffortJointInterface</hardwareInterface>
      <mechanicalReduction>1</mechanicalReduction>
    </actuator>
</transmission>

<transmission name="left_foot_roll_joint_tran">
    <type>transmission_interface/SimpleTransmission</type>
    <joint name="left_foot_roll_joint">
      <hardwareInterface>EffortJointInterface</hardwareInterface>
    </joint>
    <actuator name="left_foot_roll_joint_motor">
      <hardwareInterface>EffortJointInterface</hardwareInterface>
      <mechanicalReduction>1</mechanicalReduction>
    </actuator>
</transmission>

<transmission name="right_foot_roll_joint_tran">
    <type>transmission_interface/SimpleTransmission</type>
    <joint name="right_foot_roll_joint">
      <hardwareInterface>EffortJointInterface</hardwareInterface>
    </joint>
    <actuator name="right_foot_roll_joint_motor">
      <hardwareInterface>EffortJointInterface</hardwareInterface>
      <mechanicalReduction>1</mechanicalReduction>
    </actuator>
</transmission>


</robot>
